[2024-10-08T02:52:26.759+0000] {taskinstance.py:1157} INFO - Dependencies all met for dep_context=non-requeueable deps ti=<TaskInstance: welcome_dag.print_random_quote scheduled__2024-10-06T23:00:00+00:00 [queued]>
[2024-10-08T02:52:26.767+0000] {taskinstance.py:1157} INFO - Dependencies all met for dep_context=requeueable deps ti=<TaskInstance: welcome_dag.print_random_quote scheduled__2024-10-06T23:00:00+00:00 [queued]>
[2024-10-08T02:52:26.768+0000] {taskinstance.py:1359} INFO - Starting attempt 1 of 1
[2024-10-08T02:52:26.779+0000] {taskinstance.py:1380} INFO - Executing <Task(PythonOperator): print_random_quote> on 2024-10-06 23:00:00+00:00
[2024-10-08T02:52:26.784+0000] {standard_task_runner.py:57} INFO - Started process 59 to run task
[2024-10-08T02:52:26.789+0000] {standard_task_runner.py:84} INFO - Running: ['***', 'tasks', 'run', 'welcome_dag', 'print_random_quote', 'scheduled__2024-10-06T23:00:00+00:00', '--job-id', '7', '--raw', '--subdir', 'DAGS_FOLDER/test.py', '--cfg-path', '/tmp/tmp62z1h4p6']
[2024-10-08T02:52:26.791+0000] {standard_task_runner.py:85} INFO - Job 7: Subtask print_random_quote
[2024-10-08T02:52:26.860+0000] {task_command.py:415} INFO - Running <TaskInstance: welcome_dag.print_random_quote scheduled__2024-10-06T23:00:00+00:00 [running]> on host 9fc032ac144c
[2024-10-08T02:52:26.933+0000] {taskinstance.py:1660} INFO - Exporting env vars: AIRFLOW_CTX_DAG_OWNER='***' AIRFLOW_CTX_DAG_ID='welcome_dag' AIRFLOW_CTX_TASK_ID='print_random_quote' AIRFLOW_CTX_EXECUTION_DATE='2024-10-06T23:00:00+00:00' AIRFLOW_CTX_TRY_NUMBER='1' AIRFLOW_CTX_DAG_RUN_ID='scheduled__2024-10-06T23:00:00+00:00'
[2024-10-08T02:52:27.697+0000] {taskinstance.py:1935} ERROR - Task failed with exception
Traceback (most recent call last):
  File "/home/airflow/.local/lib/python3.8/site-packages/urllib3/connectionpool.py", line 714, in urlopen
    httplib_response = self._make_request(
  File "/home/airflow/.local/lib/python3.8/site-packages/urllib3/connectionpool.py", line 403, in _make_request
    self._validate_conn(conn)
  File "/home/airflow/.local/lib/python3.8/site-packages/urllib3/connectionpool.py", line 1053, in _validate_conn
    conn.connect()
  File "/home/airflow/.local/lib/python3.8/site-packages/urllib3/connection.py", line 419, in connect
    self.sock = ssl_wrap_socket(
  File "/home/airflow/.local/lib/python3.8/site-packages/urllib3/util/ssl_.py", line 449, in ssl_wrap_socket
    ssl_sock = _ssl_wrap_socket_impl(
  File "/home/airflow/.local/lib/python3.8/site-packages/urllib3/util/ssl_.py", line 493, in _ssl_wrap_socket_impl
    return ssl_context.wrap_socket(sock, server_hostname=server_hostname)
  File "/usr/local/lib/python3.8/ssl.py", line 500, in wrap_socket
    return self.sslsocket_class._create(
  File "/usr/local/lib/python3.8/ssl.py", line 1073, in _create
    self.do_handshake()
  File "/usr/local/lib/python3.8/ssl.py", line 1342, in do_handshake
    self._sslobj.do_handshake()
ssl.SSLCertVerificationError: [SSL: CERTIFICATE_VERIFY_FAILED] certificate verify failed: certificate has expired (_ssl.c:1131)

During handling of the above exception, another exception occurred:

Traceback (most recent call last):
  File "/home/airflow/.local/lib/python3.8/site-packages/requests/adapters.py", line 486, in send
    resp = conn.urlopen(
  File "/home/airflow/.local/lib/python3.8/site-packages/urllib3/connectionpool.py", line 798, in urlopen
    retries = retries.increment(
  File "/home/airflow/.local/lib/python3.8/site-packages/urllib3/util/retry.py", line 592, in increment
    raise MaxRetryError(_pool, url, error or ResponseError(cause))
urllib3.exceptions.MaxRetryError: HTTPSConnectionPool(host='api.quotable.io', port=443): Max retries exceeded with url: /random (Caused by SSLError(SSLCertVerificationError(1, '[SSL: CERTIFICATE_VERIFY_FAILED] certificate verify failed: certificate has expired (_ssl.c:1131)')))

During handling of the above exception, another exception occurred:

Traceback (most recent call last):
  File "/home/airflow/.local/lib/python3.8/site-packages/airflow/operators/python.py", line 192, in execute
    return_value = self.execute_callable()
  File "/home/airflow/.local/lib/python3.8/site-packages/airflow/operators/python.py", line 209, in execute_callable
    return self.python_callable(*self.op_args, **self.op_kwargs)
  File "/opt/airflow/dags/test.py", line 19, in print_random_quote
    response = requests.get('https://api.quotable.io/random')
  File "/home/airflow/.local/lib/python3.8/site-packages/requests/api.py", line 73, in get
    return request("get", url, params=params, **kwargs)
  File "/home/airflow/.local/lib/python3.8/site-packages/requests/api.py", line 59, in request
    return session.request(method=method, url=url, **kwargs)
  File "/home/airflow/.local/lib/python3.8/site-packages/requests/sessions.py", line 589, in request
    resp = self.send(prep, **send_kwargs)
  File "/home/airflow/.local/lib/python3.8/site-packages/requests/sessions.py", line 703, in send
    r = adapter.send(request, **kwargs)
  File "/home/airflow/.local/lib/python3.8/site-packages/requests/adapters.py", line 517, in send
    raise SSLError(e, request=request)
requests.exceptions.SSLError: HTTPSConnectionPool(host='api.quotable.io', port=443): Max retries exceeded with url: /random (Caused by SSLError(SSLCertVerificationError(1, '[SSL: CERTIFICATE_VERIFY_FAILED] certificate verify failed: certificate has expired (_ssl.c:1131)')))
[2024-10-08T02:52:27.727+0000] {taskinstance.py:1398} INFO - Marking task as FAILED. dag_id=welcome_dag, task_id=print_random_quote, execution_date=20241006T230000, start_date=20241008T025226, end_date=20241008T025227
[2024-10-08T02:52:27.741+0000] {standard_task_runner.py:104} ERROR - Failed to execute job 7 for task print_random_quote (HTTPSConnectionPool(host='api.quotable.io', port=443): Max retries exceeded with url: /random (Caused by SSLError(SSLCertVerificationError(1, '[SSL: CERTIFICATE_VERIFY_FAILED] certificate verify failed: certificate has expired (_ssl.c:1131)'))); 59)
[2024-10-08T02:52:27.768+0000] {local_task_job_runner.py:228} INFO - Task exited with return code 1
[2024-10-08T02:52:27.806+0000] {taskinstance.py:2776} INFO - 0 downstream tasks scheduled from follow-on schedule check
